<?xml version="1.0" encoding="UTF-8"?>
<!-- Generated by org.testng.reporters.JUnitReportReporter -->
<testsuite skipped="0" hostname="LAPTOP-D2GVCL39" name="assertion.SoftAssertionClass" tests="4" failures="3" timestamp="2022-05-04T09:26:07 IST" time="0.099" errors="0">
  <testcase name="A" time="0.067" classname="assertion.SoftAssertionClass">
    <failure type="java.lang.AssertionError" message="The following asserts failed:
	expected [4500] but found [450],
	did not expect [450] but found [450]">
      <![CDATA[java.lang.AssertionError: The following asserts failed:
expected [4500] but found [450],
did not expect [450] but found [450]
at org.testng.asserts.SoftAssert.assertAll(SoftAssert.java:47)
at org.testng.asserts.SoftAssert.assertAll(SoftAssert.java:31)
at assertion.SoftAssertionClass.A(SoftAssertionClass.java:42)
at sun.reflect.NativeMethodAccessorImpl.invoke0(Native Method)
at sun.reflect.NativeMethodAccessorImpl.invoke(Unknown Source)
at sun.reflect.DelegatingMethodAccessorImpl.invoke(Unknown Source)
at java.lang.reflect.Method.invoke(Unknown Source)
at org.testng.internal.MethodInvocationHelper.invokeMethod(MethodInvocationHelper.java:132)
at org.testng.internal.TestInvoker.invokeMethod(TestInvoker.java:599)
at org.testng.internal.TestInvoker.invokeTestMethod(TestInvoker.java:174)
at org.testng.internal.MethodRunner.runInSequence(MethodRunner.java:46)
at org.testng.internal.TestInvoker$MethodInvocationAgent.invoke(TestInvoker.java:822)
at org.testng.internal.TestInvoker.invokeTestMethods(TestInvoker.java:147)
at org.testng.internal.TestMethodWorker.invokeTestMethods(TestMethodWorker.java:146)
at org.testng.internal.TestMethodWorker.run(TestMethodWorker.java:128)
at java.util.concurrent.ThreadPoolExecutor.runWorker(Unknown Source)
at java.util.concurrent.ThreadPoolExecutor$Worker.run(Unknown Source)
at java.lang.Thread.run(Unknown Source)
]]>
    </failure>
  </testcase> <!-- A -->
  <system-out/>
  <testcase name="verifyUserCanUploadFile" time="0.007" classname="assertion.SoftAssertionClass">
    <failure type="java.lang.AssertionError" message="The following asserts failed:
	Object got initialized falsly expected [null] but found [ktctc.DM21MavenProject.FileUploadClass@28467807]">
      <![CDATA[java.lang.AssertionError: The following asserts failed:
Object got initialized falsly expected [null] but found [ktctc.DM21MavenProject.FileUploadClass@28467807]
at org.testng.asserts.SoftAssert.assertAll(SoftAssert.java:47)
at org.testng.asserts.SoftAssert.assertAll(SoftAssert.java:31)
at assertion.SoftAssertionClass.verifyUserCanUploadFile(SoftAssertionClass.java:53)
at sun.reflect.NativeMethodAccessorImpl.invoke0(Native Method)
at sun.reflect.NativeMethodAccessorImpl.invoke(Unknown Source)
at sun.reflect.DelegatingMethodAccessorImpl.invoke(Unknown Source)
at java.lang.reflect.Method.invoke(Unknown Source)
at org.testng.internal.MethodInvocationHelper.invokeMethod(MethodInvocationHelper.java:132)
at org.testng.internal.TestInvoker.invokeMethod(TestInvoker.java:599)
at org.testng.internal.TestInvoker.invokeTestMethod(TestInvoker.java:174)
at org.testng.internal.MethodRunner.runInSequence(MethodRunner.java:46)
at org.testng.internal.TestInvoker$MethodInvocationAgent.invoke(TestInvoker.java:822)
at org.testng.internal.TestInvoker.invokeTestMethods(TestInvoker.java:147)
at org.testng.internal.TestMethodWorker.invokeTestMethods(TestMethodWorker.java:146)
at org.testng.internal.TestMethodWorker.run(TestMethodWorker.java:128)
at java.util.concurrent.ThreadPoolExecutor.runWorker(Unknown Source)
at java.util.concurrent.ThreadPoolExecutor$Worker.run(Unknown Source)
at java.lang.Thread.run(Unknown Source)
]]>
    </failure>
  </testcase> <!-- verifyUserCanUploadFile -->
  <system-out/>
  <testcase name="zTestCase" time="0.017" classname="assertion.SoftAssertionClass"/>
  <system-out/>
  <testcase name="B" time="0.008" classname="assertion.SoftAssertionClass">
    <failure type="java.lang.AssertionError" message="The following asserts failed:
	User is displayed after deletion expected [false] but found [true]">
      <![CDATA[java.lang.AssertionError: The following asserts failed:
User is displayed after deletion expected [false] but found [true]
at org.testng.asserts.SoftAssert.assertAll(SoftAssert.java:47)
at org.testng.asserts.SoftAssert.assertAll(SoftAssert.java:31)
at assertion.SoftAssertionClass.B(SoftAssertionClass.java:24)
at sun.reflect.NativeMethodAccessorImpl.invoke0(Native Method)
at sun.reflect.NativeMethodAccessorImpl.invoke(Unknown Source)
at sun.reflect.DelegatingMethodAccessorImpl.invoke(Unknown Source)
at java.lang.reflect.Method.invoke(Unknown Source)
at org.testng.internal.MethodInvocationHelper.invokeMethod(MethodInvocationHelper.java:132)
at org.testng.internal.TestInvoker.invokeMethod(TestInvoker.java:599)
at org.testng.internal.TestInvoker.invokeTestMethod(TestInvoker.java:174)
at org.testng.internal.MethodRunner.runInSequence(MethodRunner.java:46)
at org.testng.internal.TestInvoker$MethodInvocationAgent.invoke(TestInvoker.java:822)
at org.testng.internal.TestInvoker.invokeTestMethods(TestInvoker.java:147)
at org.testng.internal.TestMethodWorker.invokeTestMethods(TestMethodWorker.java:146)
at org.testng.internal.TestMethodWorker.run(TestMethodWorker.java:128)
at java.util.concurrent.ThreadPoolExecutor.runWorker(Unknown Source)
at java.util.concurrent.ThreadPoolExecutor$Worker.run(Unknown Source)
at java.lang.Thread.run(Unknown Source)
]]>
    </failure>
  </testcase> <!-- B -->
  <system-out/>
</testsuite> <!-- assertion.SoftAssertionClass -->
